Workbook

Sheet วิธีใช้
A1: Test Plan — Zyra World Mobile App (QA)
A3: ที่มา | B3: zyra-doc/plan/MobileApp/test-plan.md (2026-10-02) · ค่าจาก ux-ui-plan.md, spec.md, technical-design.md, task-breakdown.md
A4: สถานะงาน | B4: ยังไม่มีโค้ด mobile ให้รัน — รายการนี้เตรียมไว้ล่วงหน้า ใช้เป็น acceptance ของแต่ละ task
A5: mockup หน้าที่ยังไม่มีใน Figma | B5: https://zyra-mobile-ui-proposals.vercel.app
A6: กฎ Comp 80% | B6: ก่อนเปลี่ยน ClickUp task เป็น Completed ต้องทดสอบผ่าน ≥ 80% ของรายการที่เกี่ยวข้อง (ดูชีต สรุป)
A8: ช่องที่ QA กรอก | B8: เฉพาะช่องพื้นเหลืองในชีต Frontend / Backend: สถานะ · ผู้ทดสอบ · วันที่ทดสอบ · เครื่อง / ช่องทาง · ลิงก์ bug · หมายเหตุ (ช่องอื่นอย่าแก้)
A10: สถานะ (dropdown)
A11: ยังไม่ทดสอบ | B11: ค่าเริ่มต้น
A12: ผ่าน | B12: ผลตรงตามคอลัมน์ ผลที่คาด
A13: ไม่ผ่าน | B13: ใส่ลิงก์ bug ในคอลัมน์ ลิงก์ bug
A14: Blocked | B14: ยังทดสอบไม่ได้ — ดูคอลัมน์ เหตุที่ blocked (รอ UI จาก design / รอมติ / Phase หลัง)
A16: Priority
A17: P0 | B17: กั้นการขึ้น store หรือใช้งานหลักไม่ได้
A18: P1 | B18: ฟีเจอร์หลักของรอบแรก
A19: P2 | B19: รายละเอียด / edge case
A20: - | B20: ยังไม่กำหนด (รอมติหรือ Phase หลัง)
A22: ตัวอย่างการกรอก
A23: FE-MEET-10 | B23: สถานะ = ผ่าน · ผู้ทดสอบ = QA ชื่อเล่น · วันที่ = 2026-10-20 · เครื่อง = iPhone 13 / แอป iOS 1.0.0 (TestFlight) · หมายเหตุ = สลับคนพูดช้า ~1 วิ
A25: เครื่องทดสอบ
A26: เครื่อง | B26: ขนาด / ใช้ทดสอบ
A27: iPhone SE (3rd) | B27: 375×667 · จอเล็ก · Spatial 667×375
A28: iPhone 13 / 14 | B28: 390×844 · เครื่องหลัก (ขนาด Figma)
A29: iPhone 14 Pro Max | B29: 430×932 · จอใหญ่
A30: Samsung Galaxy S23 หรือ Pixel 7 | B30: 393×873 · Android หลัก
A31: Android เครื่องกลาง (Galaxy A54 / Pixel 6a) | B31: performance EP-01
A32: iPad mini | B32: 744×1133 · tablet + Split View
A33: iPad Pro 12.9" | B33: 1024×1366 · tablet ใหญ่
A34: Galaxy Tab | B34: 800×1280 · Android tablet
A35: Desktop Chrome | B35: ฝั่งคนดู / คนในห้องที่ใช้ desktop + EP-02 desktop
A37: ข้อมูลที่ต้องเตรียม | B37: บัญชีทดสอบ ≥ 4 คน (Owner, Admin, Member 2) · workspace ทดสอบที่มีห้องประชุม ห้องล็อก Circle spotlight marker และ 2 floor · Google account / Apple ID ทดสอบ · Network Link Conditioner (iOS) / Chrome DevTools throttling สำหรับเน็ตแย่

Sheet สรุป
A1: สรุปผลทดสอบ (คำนวณจากคอลัมน์ สถานะ อัตโนมัติ)
A3: ส่วน | B3: กลุ่ม | C3: หัวข้อกลุ่ม | D3: ทั้งหมด | E3: ผ่าน | F3: ไม่ผ่าน | G3: Blocked | H3: ยังไม่ทดสอบ | I3: % ผ่าน | J3: ถึง 80% แล้ว? | K3: P0 ทั้งหมด | L3: P0 ผ่าน
A4: Frontend | B4: FE-ENV | C4: ตัวตัดสิน UI มือถือ และขนาดจอ (EC-03 · task 0.41–0.44, 1.16) | D4: =COUNTIFS(Frontend!$B$2:$B$180,$B4) | E4: =COUNTIFS(Frontend!$B$2:$B$180,$B4,Frontend!$I$2:$I$180,"ผ่าน") | F4: =COUNTIFS(Frontend!$B$2:$B$180,$B4,Frontend!$I$2:$I$180,"ไม่ผ่าน") | G4: =COUNTIFS(Frontend!$B$2:$B$180,$B4,Frontend!$I$2:$I$180,"Blocked") | H4: =COUNTIFS(Frontend!$B$2:$B$180,$B4,Frontend!$I$2:$I$180,"ยังไม่ทดสอบ") | I4: =IF(D4=0,0,E4/D4) | J4: =IF(I4>=0.8,"ถึงแล้ว","ยังไม่ถึง") | K4: =COUNTIFS(Frontend!$B$2:$B$180,$B4,Frontend!$D$2:$D$180,"P0") | L4: =COUNTIFS(Frontend!$B$2:$B$180,$B4,Frontend!$D$2:$D$180,"P0",Frontend!$I$2:$I$180,"ผ่าน")
A5: Frontend | B5: FE-ONB | C5: ติดตั้ง เปิดแอป login (HP-07 · task 0.31–0.33, 0.46, 1.2–1.5) | D5: =COUNTIFS(Frontend!$B$2:$B$180,$B5) | E5: =COUNTIFS(Frontend!$B$2:$B$180,$B5,Frontend!$I$2:$I$180,"ผ่าน") | F5: =COUNTIFS(Frontend!$B$2:$B$180,$B5,Frontend!$I$2:$I$180,"ไม่ผ่าน") | G5: =COUNTIFS(Frontend!$B$2:$B$180,$B5,Frontend!$I$2:$I$180,"Blocked") | H5: =COUNTIFS(Frontend!$B$2:$B$180,$B5,Frontend!$I$2:$I$180,"ยังไม่ทดสอบ") | I5: =IF(D5=0,0,E5/D5) | J5: =IF(I5>=0.8,"ถึงแล้ว","ยังไม่ถึง") | K5: =COUNTIFS(Frontend!$B$2:$B$180,$B5,Frontend!$D$2:$D$180,"P0") | L5: =COUNTIFS(Frontend!$B$2:$B$180,$B5,Frontend!$D$2:$D$180,"P0",Frontend!$I$2:$I$180,"ผ่าน")
A6: Frontend | B6: FE-MODE | C6: เลือกโหมด Lite / Spatial และหน้า Rotate (HP-03 · task 0.12–0.15, 0.42) | D6: =COUNTIFS(Frontend!$B$2:$B$180,$B6) | E6: =COUNTIFS(Frontend!$B$2:$B$180,$B6,Frontend!$I$2:$I$180,"ผ่าน") | F6: =COUNTIFS(Frontend!$B$2:$B$180,$B6,Frontend!$I$2:$I$180,"ไม่ผ่าน") | G6: =COUNTIFS(Frontend!$B$2:$B$180,$B6,Frontend!$I$2:$I$180,"Blocked") | H6: =COUNTIFS(Frontend!$B$2:$B$180,$B6,Frontend!$I$2:$I$180,"ยังไม่ทดสอบ") | I6: =IF(D6=0,0,E6/D6) | J6: =IF(I6>=0.8,"ถึงแล้ว","ยังไม่ถึง") | K6: =COUNTIFS(Frontend!$B$2:$B$180,$B6,Frontend!$D$2:$D$180,"P0") | L6: =COUNTIFS(Frontend!$B$2:$B$180,$B6,Frontend!$D$2:$D$180,"P0",Frontend!$I$2:$I$180,"ผ่าน")
A7: Frontend | B7: FE-LITE | C7: Lite Home และ navigation (HP-03, HP-06 · task 0.14, 0.28–0.30) | D7: =COUNTIFS(Frontend!$B$2:$B$180,$B7) | E7: =COUNTIFS(Frontend!$B$2:$B$180,$B7,Frontend!$I$2:$I$180,"ผ่าน") | F7: =COUNTIFS(Frontend!$B$2:$B$180,$B7,Frontend!$I$2:$I$180,"ไม่ผ่าน") | G7: =COUNTIFS(Frontend!$B$2:$B$180,$B7,Frontend!$I$2:$I$180,"Blocked") | H7: =COUNTIFS(Frontend!$B$2:$B$180,$B7,Frontend!$I$2:$I$180,"ยังไม่ทดสอบ") | I7: =IF(D7=0,0,E7/D7) | J7: =IF(I7>=0.8,"ถึงแล้ว","ยังไม่ถึง") | K7: =COUNTIFS(Frontend!$B$2:$B$180,$B7,Frontend!$D$2:$D$180,"P0") | L7: =COUNTIFS(Frontend!$B$2:$B$180,$B7,Frontend!$D$2:$D$180,"P0",Frontend!$I$2:$I$180,"ผ่าน")
A8: Frontend | B8: FE-VO | C8: Spatial Mode บนแมพ (HP-03 · task 0.3–0.7) | D8: =COUNTIFS(Frontend!$B$2:$B$180,$B8) | E8: =COUNTIFS(Frontend!$B$2:$B$180,$B8,Frontend!$I$2:$I$180,"ผ่าน") | F8: =COUNTIFS(Frontend!$B$2:$B$180,$B8,Frontend!$I$2:$I$180,"ไม่ผ่าน") | G8: =COUNTIFS(Frontend!$B$2:$B$180,$B8,Frontend!$I$2:$I$180,"Blocked") | H8: =COUNTIFS(Frontend!$B$2:$B$180,$B8,Frontend!$I$2:$I$180,"ยังไม่ทดสอบ") | I8: =IF(D8=0,0,E8/D8) | J8: =IF(I8>=0.8,"ถึงแล้ว","ยังไม่ถึง") | K8: =COUNTIFS(Frontend!$B$2:$B$180,$B8,Frontend!$D$2:$D$180,"P0") | L8: =COUNTIFS(Frontend!$B$2:$B$180,$B8,Frontend!$D$2:$D$180,"P0",Frontend!$I$2:$I$180,"ผ่าน")
A9: Frontend | B9: FE-MEET | C9: Meeting (HP-04 · task 0.8, 0.17–0.20, 0.45) | D9: =COUNTIFS(Frontend!$B$2:$B$180,$B9) | E9: =COUNTIFS(Frontend!$B$2:$B$180,$B9,Frontend!$I$2:$I$180,"ผ่าน") | F9: =COUNTIFS(Frontend!$B$2:$B$180,$B9,Frontend!$I$2:$I$180,"ไม่ผ่าน") | G9: =COUNTIFS(Frontend!$B$2:$B$180,$B9,Frontend!$I$2:$I$180,"Blocked") | H9: =COUNTIFS(Frontend!$B$2:$B$180,$B9,Frontend!$I$2:$I$180,"ยังไม่ทดสอบ") | I9: =IF(D9=0,0,E9/D9) | J9: =IF(I9>=0.8,"ถึงแล้ว","ยังไม่ถึง") | K9: =COUNTIFS(Frontend!$B$2:$B$180,$B9,Frontend!$D$2:$D$180,"P0") | L9: =COUNTIFS(Frontend!$B$2:$B$180,$B9,Frontend!$D$2:$D$180,"P0",Frontend!$I$2:$I$180,"ผ่าน")
A10: Frontend | B10: FE-CHAT | C10: Chat (HP-05 · task 0.21–0.27, 0.37) | D10: =COUNTIFS(Frontend!$B$2:$B$180,$B10) | E10: =COUNTIFS(Frontend!$B$2:$B$180,$B10,Frontend!$I$2:$I$180,"ผ่าน") | F10: =COUNTIFS(Frontend!$B$2:$B$180,$B10,Frontend!$I$2:$I$180,"ไม่ผ่าน") | G10: =COUNTIFS(Frontend!$B$2:$B$180,$B10,Frontend!$I$2:$I$180,"Blocked") | H10: =COUNTIFS(Frontend!$B$2:$B$180,$B10,Frontend!$I$2:$I$180,"ยังไม่ทดสอบ") | I10: =IF(D10=0,0,E10/D10) | J10: =IF(I10>=0.8,"ถึงแล้ว","ยังไม่ถึง") | K10: =COUNTIFS(Frontend!$B$2:$B$180,$B10,Frontend!$D$2:$D$180,"P0") | L10: =COUNTIFS(Frontend!$B$2:$B$180,$B10,Frontend!$D$2:$D$180,"P0",Frontend!$I$2:$I$180,"ผ่าน")
A11: Frontend | B11: FE-PUSH | C11: Push notification ฝั่งเครื่อง (HP-08 · task 0.34, 1.8, 2.5, 2.6) | D11: =COUNTIFS(Frontend!$B$2:$B$180,$B11) | E11: =COUNTIFS(Frontend!$B$2:$B$180,$B11,Frontend!$I$2:$I$180,"ผ่าน") | F11: =COUNTIFS(Frontend!$B$2:$B$180,$B11,Frontend!$I$2:$I$180,"ไม่ผ่าน") | G11: =COUNTIFS(Frontend!$B$2:$B$180,$B11,Frontend!$I$2:$I$180,"Blocked") | H11: =COUNTIFS(Frontend!$B$2:$B$180,$B11,Frontend!$I$2:$I$180,"ยังไม่ทดสอบ") | I11: =IF(D11=0,0,E11/D11) | J11: =IF(I11>=0.8,"ถึงแล้ว","ยังไม่ถึง") | K11: =COUNTIFS(Frontend!$B$2:$B$180,$B11,Frontend!$D$2:$D$180,"P0") | L11: =COUNTIFS(Frontend!$B$2:$B$180,$B11,Frontend!$D$2:$D$180,"P0",Frontend!$I$2:$I$180,"ผ่าน")
A12: Frontend | B12: FE-PERM | C12: สิทธิ์กล้องและไมค์ (HP-09 · task 0.35, 1.14) | D12: =COUNTIFS(Frontend!$B$2:$B$180,$B12) | E12: =COUNTIFS(Frontend!$B$2:$B$180,$B12,Frontend!$I$2:$I$180,"ผ่าน") | F12: =COUNTIFS(Frontend!$B$2:$B$180,$B12,Frontend!$I$2:$I$180,"ไม่ผ่าน") | G12: =COUNTIFS(Frontend!$B$2:$B$180,$B12,Frontend!$I$2:$I$180,"Blocked") | H12: =COUNTIFS(Frontend!$B$2:$B$180,$B12,Frontend!$I$2:$I$180,"ยังไม่ทดสอบ") | I12: =IF(D12=0,0,E12/D12) | J12: =IF(I12>=0.8,"ถึงแล้ว","ยังไม่ถึง") | K12: =COUNTIFS(Frontend!$B$2:$B$180,$B12,Frontend!$D$2:$D$180,"P0") | L12: =COUNTIFS(Frontend!$B$2:$B$180,$B12,Frontend!$D$2:$D$180,"P0",Frontend!$I$2:$I$180,"ผ่าน")
A13: Frontend | B13: FE-CONN | C13: เน็ตหลุด / เน็ตแย่ (HP-10, EP-02 · task 0.36, 0.40, 1.11) | D13: =COUNTIFS(Frontend!$B$2:$B$180,$B13) | E13: =COUNTIFS(Frontend!$B$2:$B$180,$B13,Frontend!$I$2:$I$180,"ผ่าน") | F13: =COUNTIFS(Frontend!$B$2:$B$180,$B13,Frontend!$I$2:$I$180,"ไม่ผ่าน") | G13: =COUNTIFS(Frontend!$B$2:$B$180,$B13,Frontend!$I$2:$I$180,"Blocked") | H13: =COUNTIFS(Frontend!$B$2:$B$180,$B13,Frontend!$I$2:$I$180,"ยังไม่ทดสอบ") | I13: =IF(D13=0,0,E13/D13) | J13: =IF(I13>=0.8,"ถึงแล้ว","ยังไม่ถึง") | K13: =COUNTIFS(Frontend!$B$2:$B$180,$B13,Frontend!$D$2:$D$180,"P0") | L13: =COUNTIFS(Frontend!$B$2:$B$180,$B13,Frontend!$D$2:$D$180,"P0",Frontend!$I$2:$I$180,"ผ่าน")
A14: Frontend | B14: FE-PERF | C14: Performance fallback (EP-01 · task 0.38, 0.39, 1.15) | D14: =COUNTIFS(Frontend!$B$2:$B$180,$B14) | E14: =COUNTIFS(Frontend!$B$2:$B$180,$B14,Frontend!$I$2:$I$180,"ผ่าน") | F14: =COUNTIFS(Frontend!$B$2:$B$180,$B14,Frontend!$I$2:$I$180,"ไม่ผ่าน") | G14: =COUNTIFS(Frontend!$B$2:$B$180,$B14,Frontend!$I$2:$I$180,"Blocked") | H14: =COUNTIFS(Frontend!$B$2:$B$180,$B14,Frontend!$I$2:$I$180,"ยังไม่ทดสอบ") | I14: =IF(D14=0,0,E14/D14) | J14: =IF(I14>=0.8,"ถึงแล้ว","ยังไม่ถึง") | K14: =COUNTIFS(Frontend!$B$2:$B$180,$B14,Frontend!$D$2:$D$180,"P0") | L14: =COUNTIFS(Frontend!$B$2:$B$180,$B14,Frontend!$D$2:$D$180,"P0",Frontend!$I$2:$I$180,"ผ่าน")
A15: Frontend | B15: FE-SPOT | C15: Spotlight (HP-11 · task 0.47–0.51) | D15: =COUNTIFS(Frontend!$B$2:$B$180,$B15) | E15: =COUNTIFS(Frontend!$B$2:$B$180,$B15,Frontend!$I$2:$I$180,"ผ่าน") | F15: =COUNTIFS(Frontend!$B$2:$B$180,$B15,Frontend!$I$2:$I$180,"ไม่ผ่าน") | G15: =COUNTIFS(Frontend!$B$2:$B$180,$B15,Frontend!$I$2:$I$180,"Blocked") | H15: =COUNTIFS(Frontend!$B$2:$B$180,$B15,Frontend!$I$2:$I$180,"ยังไม่ทดสอบ") | I15: =IF(D15=0,0,E15/D15) | J15: =IF(I15>=0.8,"ถึงแล้ว","ยังไม่ถึง") | K15: =COUNTIFS(Frontend!$B$2:$B$180,$B15,Frontend!$D$2:$D$180,"P0") | L15: =COUNTIFS(Frontend!$B$2:$B$180,$B15,Frontend!$D$2:$D$180,"P0",Frontend!$I$2:$I$180,"ผ่าน")
... A17: Frontend | B17: FE-STORE | C17: ก่อนส่ง store | D17: =COUNTIFS(Frontend!$B$2:$B$180,$B17) | E17: =COUNTIFS(Frontend!$B$2:$B$180,$B17,Frontend!$I$2:$I$180,"ผ่าน") | F17: =COUNTIFS(Frontend!$B$2:$B$180,$B17,Frontend!$I$2:$I$180,"ไม่ผ่าน") | G17: =COUNTIFS(Frontend!$B$2:$B$180,$B17,Frontend!$I$2:$I$180,"Blocked") | H17: =COUNTIFS(Frontend!$B$2:$B$180,$B17,Frontend!$I$2:$I$180,"ยังไม่ทดสอบ") | I17: =IF(D17=0,0,E17/D17) | J17: =IF(I17>=0.8,"ถึงแล้ว","ยังไม่ถึง") | K17: =COUNTIFS(Frontend!$B$2:$B$180,$B17,Frontend!$D$2:$D$180,"P0") | L17: =COUNTIFS(Frontend!$B$2:$B$180,$B17,Frontend!$D$2:$D$180,"P0",Frontend!$I$2:$I$180,"ผ่าน")
A18: Backend | B18: BE-AUTH | C18: login (zyra-api · task 1.4, 1.5) | D18: =COUNTIFS(Backend!$B$2:$B$54,$B18) | E18: =COUNTIFS(Backend!$B$2:$B$54,$B18,Backend!$I$2:$I$54,"ผ่าน") | F18: =COUNTIFS(Backend!$B$2:$B$54,$B18,Backend!$I$2:$I$54,"ไม่ผ่าน") | G18: =COUNTIFS(Backend!$B$2:$B$54,$B18,Backend!$I$2:$I$54,"Blocked") | H18: =COUNTIFS(Backend!$B$2:$B$54,$B18,Backend!$I$2:$I$54,"ยังไม่ทดสอบ") | I18: =IF(D18=0,0,E18/D18) | J18: =IF(I18>=0.8,"ถึงแล้ว","ยังไม่ถึง") | K18: =COUNTIFS(Backend!$B$2:$B$54,$B18,Backend!$D$2:$D$54,"P0") | L18: =COUNTIFS(Backend!$B$2:$B$54,$B18,Backend!$D$2:$D$54,"P0",Backend!$I$2:$I$54,"ผ่าน")
A19: Backend | B19: BE-DEV | C19: device token (zyra-api · task 2.1) | D19: =COUNTIFS(Backend!$B$2:$B$54,$B19) | E19: =COUNTIFS(Backend!$B$2:$B$54,$B19,Backend!$I$2:$I$54,"ผ่าน") | F19: =COUNTIFS(Backend!$B$2:$B$54,$B19,Backend!$I$2:$I$54,"ไม่ผ่าน") | G19: =COUNTIFS(Backend!$B$2:$B$54,$B19,Backend!$I$2:$I$54,"Blocked") | H19: =COUNTIFS(Backend!$B$2:$B$54,$B19,Backend!$I$2:$I$54,"ยังไม่ทดสอบ") | I19: =IF(D19=0,0,E19/D19) | J19: =IF(I19>=0.8,"ถึงแล้ว","ยังไม่ถึง") | K19: =COUNTIFS(Backend!$B$2:$B$54,$B19,Backend!$D$2:$D$54,"P0") | L19: =COUNTIFS(Backend!$B$2:$B$54,$B19,Backend!$D$2:$D$54,"P0",Backend!$I$2:$I$54,"ผ่าน")
A20: Backend | B20: BE-PUSH | C20: ส่ง push (zyra-notifications, zyra-ws · task 2.2–2.6) | D20: =COUNTIFS(Backend!$B$2:$B$54,$B20) | E20: =COUNTIFS(Backend!$B$2:$B$54,$B20,Backend!$I$2:$I$54,"ผ่าน") | F20: =COUNTIFS(Backend!$B$2:$B$54,$B20,Backend!$I$2:$I$54,"ไม่ผ่าน") | G20: =COUNTIFS(Backend!$B$2:$B$54,$B20,Backend!$I$2:$I$54,"Blocked") | H20: =COUNTIFS(Backend!$B$2:$B$54,$B20,Backend!$I$2:$I$54,"ยังไม่ทดสอบ") | I20: =IF(D20=0,0,E20/D20) | J20: =IF(I20>=0.8,"ถึงแล้ว","ยังไม่ถึง") | K20: =COUNTIFS(Backend!$B$2:$B$54,$B20,Backend!$D$2:$D$54,"P0") | L20: =COUNTIFS(Backend!$B$2:$B$54,$B20,Backend!$D$2:$D$54,"P0",Backend!$I$2:$I$54,"ผ่าน")
A21: Backend | B21: BE-WS | C21: WebSocket โหมด Lite / meeting / reconnect (zyra-ws · task 0.16, 0.19, 0.48) | D21: =COUNTIFS(Backend!$B$2:$B$54,$B21) | E21: =COUNTIFS(Backend!$B$2:$B$54,$B21,Backend!$I$2:$I$54,"ผ่าน") | F21: =COUNTIFS(Backend!$B$2:$B$54,$B21,Backend!$I$2:$I$54,"ไม่ผ่าน") | G21: =COUNTIFS(Backend!$B$2:$B$54,$B21,Backend!$I$2:$I$54,"Blocked") | H21: =COUNTIFS(Backend!$B$2:$B$54,$B21,Backend!$I$2:$I$54,"ยังไม่ทดสอบ") | I21: =IF(D21=0,0,E21/D21) | J21: =IF(I21>=0.8,"ถึงแล้ว","ยังไม่ถึง") | K21: =COUNTIFS(Backend!$B$2:$B$54,$B21,Backend!$D$2:$D$54,"P0") | L21: =COUNTIFS(Backend!$B$2:$B$54,$B21,Backend!$D$2:$D$54,"P0",Backend!$I$2:$I$54,"ผ่าน")
A22: Backend | B22: BE-CHAT | C22: แชท (zyra-api, zyra-ws · task 0.25, 0.27, 0.37) | D22: =COUNTIFS(Backend!$B$2:$B$54,$B22) | E22: =COUNTIFS(Backend!$B$2:$B$54,$B22,Backend!$I$2:$I$54,"ผ่าน") | F22: =COUNTIFS(Backend!$B$2:$B$54,$B22,Backend!$I$2:$I$54,"ไม่ผ่าน") | G22: =COUNTIFS(Backend!$B$2:$B$54,$B22,Backend!$I$2:$I$54,"Blocked") | H22: =COUNTIFS(Backend!$B$2:$B$54,$B22,Backend!$I$2:$I$54,"ยังไม่ทดสอบ") | I22: =IF(D22=0,0,E22/D22) | J22: =IF(I22>=0.8,"ถึงแล้ว","ยังไม่ถึง") | K22: =COUNTIFS(Backend!$B$2:$B$54,$B22,Backend!$D$2:$D$54,"P0") | L22: =COUNTIFS(Backend!$B$2:$B$54,$B22,Backend!$D$2:$D$54,"P0",Backend!$I$2:$I$54,"ผ่าน")
A23: Backend | B23: BE-API | C23: ทั่วไป | D23: =COUNTIFS(Backend!$B$2:$B$54,$B23) | E23: =COUNTIFS(Backend!$B$2:$B$54,$B23,Backend!$I$2:$I$54,"ผ่าน") | F23: =COUNTIFS(Backend!$B$2:$B$54,$B23,Backend!$I$2:$I$54,"ไม่ผ่าน") | G23: =COUNTIFS(Backend!$B$2:$B$54,$B23,Backend!$I$2:$I$54,"Blocked") | H23: =COUNTIFS(Backend!$B$2:$B$54,$B23,Backend!$I$2:$I$54,"ยังไม่ทดสอบ") | I23: =IF(D23=0,0,E23/D23) | J23: =IF(I23>=0.8,"ถึงแล้ว","ยังไม่ถึง") | K23: =COUNTIFS(Backend!$B$2:$B$54,$B23,Backend!$D$2:$D$54,"P0") | L23: =COUNTIFS(Backend!$B$2:$B$54,$B23,Backend!$D$2:$D$54,"P0",Backend!$I$2:$I$54,"ผ่าน")
A24: รวม | D24: =SUM(D4:D23) | E24: =SUM(E4:E23) | F24: =SUM(F4:F23) | G24: =SUM(G4:G23) | H24: =SUM(H4:H23) | I24: =IF(D24=0,0,E24/D24) | J24: =IF(I24>=0.8,"ถึงแล้ว","ยังไม่ถึง") | K24: =SUM(K4:K23) | L24: =SUM(L4:L23)
A26: หมายเหตุ: % ผ่าน = ผ่าน ÷ ทั้งหมด ของกลุ่ม · เกณฑ์ 80% มาจากกฎทีม "ก่อนปรับ Comp ต้องเทสอย่างน้อย 80%" (Comp = Completed ใน ClickUp)

Sheet Frontend
A1: ID | B1: กลุ่ม | C1: หัวข้อกลุ่ม | D1: Priority | E1: กรณี | F1: ขั้นตอน | G1: ผลที่คาด | H1: อ้างอิง | I1: สถานะ | J1: เหตุที่ blocked | K1: ผู้ทดสอบ | L1: วันที่ทดสอบ | M1: เครื่อง / ช่องทาง | N1: ลิงก์ bug | O1: หมายเหตุ
A2: FE-ENV-01 | B2: FE-ENV | C2: ตัวตัดสิน UI มือถือ และขนาดจอ (EC-03 · task 0.41–0.44, 1.16) | D2: P0 | E2: แอปบนมือถือและ tablet ใช้ UI มือถือเสมอ | F2: เปิดแอปบน iPhone, Android, iPad | G2: ได้หน้า Select workspace mode / Lite / Spatial ไม่ใช่หน้า desktop | H2: §17.6 | I2: ยังไม่ทดสอบ
A3: FE-ENV-02 | B3: FE-ENV | C3: ตัวตัดสิน UI มือถือ และขนาดจอ (EC-03 · task 0.41–0.44, 1.16) | D3: P0 | E3: เว็บบนจอสัมผัส ด้านยาว ≤ 1366 | F3: เปิดเว็บใน Safari iPad Pro, Chrome Android | G3: ได้ UI มือถือ | H3: §17.6 | I3: ยังไม่ทดสอบ
A4: FE-ENV-03 | B4: FE-ENV | C4: ตัวตัดสิน UI มือถือ และขนาดจอ (EC-03 · task 0.41–0.44, 1.16) | D4: P1 | E4: iPad + trackpad บนเว็บ | F4: ต่อ Magic Keyboard แล้วเปิดเว็บ | G4: ยังเป็น UI มือถือ | H4: §17.7 ข้อ 2 | I4: ยังไม่ทดสอบ
A5: FE-ENV-04 | B5: FE-ENV | C5: ตัวตัดสิน UI มือถือ และขนาดจอ (EC-03 · task 0.41–0.44, 1.16) | D5: P1 | E5: laptop จอสัมผัสด้านยาว > 1366 | F5: เปิดเว็บบน laptop จอสัมผัส (หน้าต่างแนวนอน กว้าง ≥ 768) | G5: ได้หน้า desktop เดิม (ถ้าย่อเป็นแนวตั้งจะเป็น UI มือถือตาม FE-ENV-14) | H5: §17.6 | I5: ยังไม่ทดสอบ
A6: FE-ENV-05 | B6: FE-ENV | C6: ตัวตัดสิน UI มือถือ และขนาดจอ (EC-03 · task 0.41–0.44, 1.16) | D6: P1 | E6: tablet scale | F6: iPad (ด้านสั้น ≥ 744) | G6: ขอบซ้ายขวา 24 · ปุ่มกลมขวาบน Spatial และปุ่ม Chat = 44 | H6: §17.6 | I6: ยังไม่ทดสอบ
A7: FE-ENV-06 | B7: FE-ENV | C7: ตัวตัดสิน UI มือถือ และขนาดจอ (EC-03 · task 0.41–0.44, 1.16) | D7: P1 | E7: phone scale | F7: iPhone 390 / 430 | G7: ขอบ 16 · ปุ่มกลม 32 | H7: §17.2 | I7: ยังไม่ทดสอบ
A8: FE-ENV-07 | B8: FE-ENV | C8: ตัวตัดสิน UI มือถือ และขนาดจอ (EC-03 · task 0.41–0.44, 1.16) | D8: P1 | E8: จอเล็ก 375×667 | F8: ใช้ทุกหน้าหลักบน iPhone SE | G8: ไม่มีการเลื่อนซ้ายขวา · ข้อความยาวถูกตัดเป็น … · modal สูงไม่เกิน 90% ของจอและเลื่อนได้ · คีย์บอร์ดไม่บังช่องพิมพ์ | H8: §17.6 | I8: ยังไม่ทดสอบ
A9: FE-ENV-08 | B9: FE-ENV | C9: ตัวตัดสิน UI มือถือ และขนาดจอ (EC-03 · task 0.41–0.44, 1.16) | D9: P1 | E9: Spatial บนจอเล็ก 667×375 | F9: เข้า Spatial บน iPhone SE | G9: joystick, Meeting Menu, minimap ไม่ทับกัน | H9: §17.6 | I9: ยังไม่ทดสอบ
A10: FE-ENV-09 | B10: FE-ENV | C10: ตัวตัดสิน UI มือถือ และขนาดจอ (EC-03 · task 0.41–0.44, 1.16) | D10: P1 | E10: iPad Split View | F10: แบ่งจอครึ่งตอนเครื่องแนวนอน | G10: ระบบนับเป็นแนวตั้ง (ใช้ Lite / ขึ้นหน้า Rotate ถ้าอยู่ Spatial) | H10: §17.6 | I10: ยังไม่ทดสอบ
A11: FE-ENV-10 | B11: FE-ENV | C11: ตัวตัดสิน UI มือถือ และขนาดจอ (EC-03 · task 0.41–0.44, 1.16) | D11: P1 | E11: ปรับขนาด Split View ระหว่างใช้ | F11: ลากเส้นแบ่งจอให้กว้าง/แคบ | G11: layout และ tablet scale ปรับตามทันที ไม่ค้าง | H11: TD §16.8 | I11: ยังไม่ทดสอบ
A12: FE-ENV-11 | B12: FE-ENV | C12: ตัวตัดสิน UI มือถือ และขนาดจอ (EC-03 · task 0.41–0.44, 1.16) | D12: P1 | E12: ตัวอักษรไม่ขยายตามเครื่อง | F12: Android ตั้ง font size ใหญ่สุด แล้วเปิดแอป | G12: layout ไม่แตก ตัวอักษรขนาดเดิม | H12: §17.7 ข้อ 8 | I12: ยังไม่ทดสอบ
A13: FE-ENV-12 | B13: FE-ENV | C13: ตัวตัดสิน UI มือถือ และขนาดจอ (EC-03 · task 0.41–0.44, 1.16) | D13: P2 | E13: dark mode อย่างเดียว | F13: ตั้งเครื่องเป็น light mode | G13: แอปยังเป็นธีมมืด | H13: §17.7 ข้อ 9 | I13: ยังไม่ทดสอบ
... A31: FE-ONB-13 | B31: FE-ONB | C31: ติดตั้ง เปิดแอป login (HP-07 · task 0.31–0.33, 0.46, 1.2–1.5) | D31: P1 | E31: sheet "Meet Zyra on mobile" บนเว็บ | F31: เปิดเว็บบนมือถือ รอ ~5 วิ | G31: sheet ขึ้น · Open Zyra → เปิดแอป (ถ้ามี) หรือไป App Store / Play Store · Later → ซ่อน 7 วัน | H31: task 0.33 | I31: ยังไม่ทดสอบ
A32: FE-ONB-14 | B32: FE-ONB | C32: ติดตั้ง เปิดแอป login (HP-07 · task 0.31–0.33, 0.46, 1.2–1.5) | D32: P2 | E32: ชวนติดตั้ง PWA | F32: กด Later แล้วเข้าเว็บครั้งที่ 2 | G32: ขึ้นหน้า Add to Home Screen (Android ปุ่ม Install · iOS บอกขั้นตอน) | H32: §11.6 ข้อ 2 | I32: Blocked | J32: รอ UI จาก design
A33: FE-ONB-15 | B33: FE-ONB | C33: ติดตั้ง เปิดแอป login (HP-07 · task 0.31–0.33, 0.46, 1.2–1.5) | D33: P1 | E33: แจ้งมี version ใหม่ | F33: deploy version ใหม่ระหว่างใช้แอป | G33: modal แจ้ง update ขึ้นภายใน 30 นาที | H33: clickup-spec §18 ข้อ 9 | I33: ยังไม่ทดสอบ
A34: FE-ONB-16 | B34: FE-ONB | C34: ติดตั้ง เปิดแอป login (HP-07 · task 0.31–0.33, 0.46, 1.2–1.5) | D34: P1 | E34: error ตอน login | F34: รหัสผิด · อีเมลยังไม่ยืนยัน · กด cancel ตอนเลือกบัญชี Google · ปิดเน็ต | G34: ข้อความแดง "Incorrect email or password." · sheet "Verify your email" → OTP · cancel แล้วอยู่หน้าเดิมไม่มี error · toast "Can't connect…" | H34: §22.3 · task 0.60 | I34: Blocked | J34: รอ UI จาก design
A35: FE-MODE-01 | B35: FE-MODE | C35: เลือกโหมด Lite / Spatial และหน้า Rotate (HP-03 · task 0.12–0.15, 0.42) | D35: P0 | E35: เลือกโหมดครั้งแรก | F35: เลือก workspace | G35: ขึ้นหน้า Select workspace mode (Lite / Spatial) → Confirm → sheet Keep This Setting? | H35: §3.4 | I35: ยังไม่ทดสอบ
A36: FE-MODE-02 | B36: FE-MODE | C36: เลือกโหมด Lite / Spatial และหน้า Rotate (HP-03 · task 0.12–0.15, 0.42) | D36: P0 | E36: Remind me again = จำ 1 วัน ทุก workspace | F36: เลือก Remind me again แล้วสลับไป workspace อื่นภายใน 24 ชม. | G36: ไม่ถามโหมดซ้ำ · ครบ 24 ชม. ถามใหม่ | H36: TD §16.1 | I36: ยังไม่ทดสอบ
A37: FE-MODE-03 | B37: FE-MODE | C37: เลือกโหมด Lite / Spatial และหน้า Rotate (HP-03 · task 0.12–0.15, 0.42) | D37: P1 | E37: Always = จำตลอด | F37: เลือก Always แล้วปิดเปิดแอป | G37: ไม่ถามอีก | H37: TD §16.1 | I37: ยังไม่ทดสอบ
A38: FE-MODE-04 | B38: FE-MODE | C38: เลือกโหมด Lite / Spatial และหน้า Rotate (HP-03 · task 0.12–0.15, 0.42) | D38: P0 | E38: เปลี่ยนโหมดได้จาก Settings เท่านั้น | F38: Profile → Setting → Workspace mode | G38: เปลี่ยนแล้วโหลดหน้าใหม่ในโหมดใหม่ · การหมุนเครื่องไม่สลับโหมด | H38: §3.4 | I38: ยังไม่ทดสอบ
A39: FE-MODE-05 | B39: FE-MODE | C39: เลือกโหมด Lite / Spatial และหน้า Rotate (HP-03 · task 0.12–0.15, 0.42) | D39: P0 | E39: Lite ถือแนวนอน | F39: อยู่ Lite แล้วหมุนเครื่องแนวนอน | G39: หน้า "Rotate your phone to use Lite Mode." ทับ · หมุนกลับแล้วหาย | H39: §3.5 | I39: ยังไม่ทดสอบ
A40: FE-MODE-06 | B40: FE-MODE | C40: เลือกโหมด Lite / Spatial และหน้า Rotate (HP-03 · task 0.12–0.15, 0.42) | D40: P0 | E40: Spatial ถือแนวตั้ง | F40: อยู่ Spatial แล้วหมุนแนวตั้ง | G40: หน้า Rotate ทับ · แมพหยุดวาด แต่เสียงประชุมยังต่อ · หมุนกลับแมพกลับมา | H40: §3.5, TD §16.3 | I40: ยังไม่ทดสอบ
A41: FE-MODE-07 | B41: FE-MODE | C41: เลือกโหมด Lite / Spatial และหน้า Rotate (HP-03 · task 0.12–0.15, 0.42) | D41: P1 | E41: คีย์บอร์ดไม่ทำให้หน้า Rotate เด้ง | F41: Android พิมพ์แชทใน Lite | G41: ไม่ขึ้นหน้า Rotate ตอนคีย์บอร์ดเปิด | H41: TD §16.4 | I41: ยังไม่ทดสอบ
A42: FE-MODE-08 | B42: FE-MODE | C42: เลือกโหมด Lite / Spatial และหน้า Rotate (HP-03 · task 0.12–0.15, 0.42) | D42: P0 | E42: Lite ไม่โหลดแมพ | F42: เข้า Lite แล้วดู network | G42: ไม่มีการโหลด engine / map / spritesheet | H42: TD §16.2 | I42: ยังไม่ทดสอบ
A43: FE-MODE-09 | B43: FE-MODE | C43: เลือกโหมด Lite / Spatial และหน้า Rotate (HP-03 · task 0.12–0.15, 0.42) | D43: P1 | E43: Lite เข้าเลยไม่ผ่าน pre-join | F43: เลือก Lite → Enter Workspace | G43: ไป Connecting → Lite Home ทันที (ไม่มีหน้า preview กล้อง/ชื่อตัวละคร) | H43: TD §16.1 | I43: ยังไม่ทดสอบ
A44: FE-MODE-10 | B44: FE-MODE | C44: เลือกโหมด Lite / Spatial และหน้า Rotate (HP-03 · task 0.12–0.15, 0.42) | D44: P1 | E44: Spatial ผ่าน pre-join | F44: เลือก Spatial | G44: หน้า welcome / pre-join แนวนอน → Connecting → แมพ | H44: §3.6 | I44: ยังไม่ทดสอบ
A45: FE-LITE-01 | B45: FE-LITE | C45: Lite Home และ navigation (HP-03, HP-06 · task 0.14, 0.28–0.30) | D45: P0 | E45: Lite Home | F45: เข้า Lite | G45: header workspace + Start spotlight / Instant meeting + ค้นหา + In meeting + Circle + Online / Offline | H45: §3.8 | I45: ยังไม่ทดสอบ
A46: FE-LITE-02 | B46: FE-LITE | C46: Lite Home และ navigation (HP-03, HP-06 · task 0.14, 0.28–0.30) | D46: P0 | E46: แท็บล่าง 3 ปุ่ม | F46: ดูแท็บล่าง | G46: Home / Chat / Profile แบบ icon ไม่มี label · ไม่มี Calendar · หดตอนเลื่อน | H46: §10.6 ข้อ 7 | I46: ยังไม่ทดสอบ
... A51: FE-LITE-07 | B51: FE-LITE | C51: Lite Home และ navigation (HP-03, HP-06 · task 0.14, 0.28–0.30) | D51: P1 | E51: Notification | F51: แตะกระดิ่ง | G51: หน้าเต็มจอ All / Unread · Mark as read · กลุ่ม Today / Yesterday · ยังไม่อ่าน = พื้นอ่อนกว่า | H51: task 0.29 | I51: ยังไม่ทดสอบ
A52: FE-LITE-08 | B52: FE-LITE | C52: Lite Home และ navigation (HP-03, HP-06 · task 0.14, 0.28–0.30) | D52: P1 | E52: Profile + สถานะ 4 แบบ | F52: แท็บ Profile → เปลี่ยนสถานะ | G52: Active / Busy / Away / Do not disturb + custom status · สถานะเปลี่ยนบนเครื่องอื่นด้วย | H52: §10.6 ข้อ 5 | I52: ยังไม่ทดสอบ | O52: 🎨 แถว DND
A53: FE-LITE-09 | B53: FE-LITE | C53: Lite Home และ navigation (HP-03, HP-06 · task 0.14, 0.28–0.30) | D53: P1 | E53: Setting ตามสิทธิ์ | F53: เข้า Setting ด้วย Member และ Owner/Admin | G53: Member ไม่เห็น Manage member / Environment · Owner/Admin เห็น | H53: §10.6 ข้อ 6 | I53: ยังไม่ทดสอบ
A54: FE-LITE-10 | B54: FE-LITE | C54: Lite Home และ navigation (HP-03, HP-06 · task 0.14, 0.28–0.30) | D54: P1 | E54: Switch workspace / Log out | F54: กดจาก Profile | G54: Switch กลับ Space builder · Log out ล้าง session และลบ push token ของเครื่อง | H54: task 0.30, 1.8 | I54: ยังไม่ทดสอบ
A55: FE-LITE-11 | B55: FE-LITE | C55: Lite Home และ navigation (HP-03, HP-06 · task 0.14, 0.28–0.30) | D55: P1 | E55: ฟีเจอร์ที่ยังไม่มีถูกซ่อน | F55: ไล่ดู Lite Home, Spatial, Meeting, Profile | G55: ไม่มีทางเข้า Tarot, Participation Dashboard, Quiz / Poll, AI Meeting Summary, Meeting alert · ไม่มีคำว่า Coming soon ที่ไหนเลย | H55: §19.7 | I55: ยังไม่ทดสอบ
A56: FE-LITE-12 | B56: FE-LITE | C56: Lite Home และ navigation (HP-03, HP-06 · task 0.14, 0.28–0.30) | D56: P1 | E56: Calendar ซ่อนทุกที่ | F56: ดูแท็บล่าง, ปุ่มกลม Spatial, Notification settings | G56: ไม่มี Calendar ทั้ง 3 จุด | H56: §10.6 ข้อ 7 | I56: ยังไม่ทดสอบ
A57: FE-LITE-13 | B57: FE-LITE | C57: Lite Home และ navigation (HP-03, HP-06 · task 0.14, 0.28–0.30) | D57: P1 | E57: แตะสมาชิก / แตะ Circle ใน Lite | F57: แตะคนในรายชื่อ (คนว่าง และคนที่อยู่ในห้อง) · แตะ Circle | G57: sheet โปรไฟล์มี Message / Wave · คนที่อยู่ในห้องมี Join ด้วย · ไม่มี Follow · แตะ Circle ได้ sheet "Join Circle" → เข้า Circle ได้ | H57: §22.2 · task 0.59 | I57: Blocked | J57: รอ UI จาก design
A58: FE-LITE-14 | B58: FE-LITE | C58: Lite Home และ navigation (HP-03, HP-06 · task 0.14, 0.28–0.30) | D58: P0 | E58: ลบบัญชีในแอป | F58: Profile → Account and Security → Delete account · พิมพ์อีเมลผิดแล้วถูก → Delete my account | G58: ปุ่มกดไม่ได้จนอีเมลตรง (ไม่สนตัวพิมพ์) · หน้าบอก workspace ที่จะโอนให้ใคร / ถูกลบ · ลบแล้วออกจากระบบไป Get started + toast "Your account has been deleted." · login ด้วยบัญชีเดิมไม่ได้ | H58: §20 · task 0.55 | I58: Blocked | J58: รอ UI จาก design
A59: FE-LITE-15 | B59: FE-LITE | C59: Lite Home และ navigation (HP-03, HP-06 · task 0.14, 0.28–0.30) | D59: P1 | E59: DM กับบัญชีที่ถูกลบ | F59: เปิด DM กับคนที่ลบบัญชีไปแล้ว | G59: เห็นข้อความเก่า ชื่อเป็น "Deleted user" · ช่องพิมพ์ปิด ขึ้น "This account has been deleted" | H59: §20.6 | I59: Blocked | J59: รอ UI จาก design
A60: FE-LITE-16 | B60: FE-LITE | C60: Lite Home และ navigation (HP-03, HP-06 · task 0.14, 0.28–0.30) | D60: P2 | E60: หน้าว่าง | F60: workspace ที่ไม่มีแชท / ไม่มี notification · ค้นหาคำที่ไม่มี | G60: "No conversations yet" + ปุ่ม Start a new chat · "You're all caught up" · "No results for "<คำค้น>"" · "No threads yet" | H60: §22.3 | I60: Blocked | J60: รอ UI จาก design
A61: FE-LITE-17 | B61: FE-LITE | C61: Lite Home และ navigation (HP-03, HP-06 · task 0.14, 0.28–0.30) | D61: P1 | E61: แก้โปรไฟล์ + เลือกตัวละคร | F61: Profile → การ์ดสถานะ → แก้ชื่อ รูป status → Save · Change character | G61: Save กดได้เมื่อแก้ · toast "Profile updated" · รูปใหม่ขึ้นทุกที่ · เลือกตัวละครแล้วตัวบนแมพเปลี่ยน | H61: §22.3 · task 0.61 | I61: Blocked | J61: รอ UI จาก design
...

Sheet Backend
A1: ID | B1: กลุ่ม | C1: หัวข้อกลุ่ม | D1: Priority | E1: กรณี | F1: ขั้นตอน | G1: ผลที่คาด | H1: อ้างอิง | I1: สถานะ | J1: เหตุที่ blocked | K1: ผู้ทดสอบ | L1: วันที่ทดสอบ | M1: เครื่อง / ช่องทาง | N1: ลิงก์ bug | O1: หมายเหตุ
A2: BE-AUTH-01 | B2: BE-AUTH | C2: login (zyra-api · task 1.4, 1.5) | D2: P0 | E2: Google id_token จากแอป | F2: POST /api/authen/login_google ด้วย id_token ของ client iOS / Android / web | G2: ยอมรับทั้ง 3 audience · ได้ token ใน model.APIResponse | H2: task 1.4 | I2: ยังไม่ทดสอบ
A3: BE-AUTH-02 | B3: BE-AUTH | C3: login (zyra-api · task 1.4, 1.5) | D3: P0 | E3: Google token ผิด / หมดอายุ / audience อื่น | F3: ส่ง token ไม่ถูกต้อง | G3: 401 พร้อม envelope · ไม่สร้าง user | H3: task 1.4 | I3: ยังไม่ทดสอบ
A4: BE-AUTH-03 | B4: BE-AUTH | C4: login (zyra-api · task 1.4, 1.5) | D4: P0 | E4: Sign in with Apple | F4: POST /api/authen/login_apple ด้วย identityToken | G4: ตรวจ JWT กับ Apple keys · ผูก user ด้วย sub · login ครั้งต่อไปด้วย sub เดิมได้ user เดิม | H4: task 1.5 | I4: ยังไม่ทดสอบ
A5: BE-AUTH-04 | B5: BE-AUTH | C5: login (zyra-api · task 1.4, 1.5) | D5: P1 | E5: Apple ซ่อนอีเมล | F5: login ด้วย private relay email | G5: สร้าง/ผูก user ได้ · ไม่ชนกับ user อื่น | H5: task 1.5 | I5: ยังไม่ทดสอบ
A6: BE-AUTH-05 | B6: BE-AUTH | C6: login (zyra-api · task 1.4, 1.5) | D6: P1 | E6: Apple บนเว็บ | F6: login จากเว็บ (Services ID) | G6: ใช้ endpoint เดียวกัน · ได้ user เดียวกับในแอป | H6: task 1.5 | I6: ยังไม่ทดสอบ
A7: BE-AUTH-06 | B7: BE-AUTH | C7: login (zyra-api · task 1.4, 1.5) | D7: P1 | E7: cookie / session ใน WebView | F7: login ในแอปแล้วปิดเปิดแอป | G7: session ยังอยู่ · refresh token ทำงาน | H7: TD §2 | I7: ยังไม่ทดสอบ
A8: BE-AUTH-07 | B8: BE-AUTH | C8: login (zyra-api · task 1.4, 1.5) | D8: P0 | E8: DELETE /api/user/me | F8: ลบบัญชีตัวเองด้วยอีเมลถูก / ผิด · เป็นเจ้าของ workspace ที่มีสมาชิก และที่ไม่มีสมาชิก | G8: อีเมลผิด = error · ถูก = soft-delete + email hash · workspace โอนให้คนที่อยู่นานที่สุด · workspace ไม่มีสมาชิก = ถูกลบ · token ทุกเครื่องใช้ไม่ได้ · device token ถูกลบ · เรียกด้วย route admin ไม่ได้ | H8: §20.4 · task 0.55 | I8: ยังไม่ทดสอบ
A9: BE-AUTH-08 | B9: BE-AUTH | C9: login (zyra-api · task 1.4, 1.5) | D9: P1 | E9: ชื่อของบัญชีที่ถูกลบ | F9: ดึงแชท / member list ที่มีข้อความของบัญชีที่ถูกลบ | G9: แสดง "Deleted user" + avatar ว่าง | H9: §20.5 ข้อ 5 | I9: ยังไม่ทดสอบ
A10: BE-AUTH-09 | B10: BE-AUTH | C10: login (zyra-api · task 1.4, 1.5) | D10: P1 | E10: Sign in with Apple revoke | F10: ลบบัญชีที่สมัครด้วย Apple | G10: เรียก Apple revoke token สำเร็จ · log ไม่มี token | H10: §20.4 · task 1.5 | I10: ยังไม่ทดสอบ
A11: BE-AUTH-10 | B11: BE-AUTH | C11: login (zyra-api · task 1.4, 1.5) | D11: P0 | E11: ลบแล้วไม่กระทบคนอื่น | F11: ลบบัญชีที่เป็นสมาชิก workspace, admin คนเดียวของกลุ่มแชท, จอง private zone และมี DM กับคนอื่น | G11: ไม่อยู่ในรายชื่อสมาชิก workspace / กลุ่ม · กลุ่มมี admin ใหม่ (คนที่อยู่นานที่สุด) · private zone ว่าง · อีกฝ่ายยังอ่าน DM ได้แต่ส่งไม่ได้ · ข้อความเก่าขึ้น "Deleted user" | H11: §20.6 · task 0.55 | I11: ยังไม่ทดสอบ
A12: BE-AUTH-11 | B12: BE-AUTH | C12: login (zyra-api · task 1.4, 1.5) | D12: P1 | E12: admin ลบใช้ logic เดียวกัน | F12: admin ของระบบลบบัญชีเดียวกันจากหน้า admin | G12: ผลเหมือน BE-AUTH-10 ทุกข้อ · admin ลบตัวเองไม่ได้ · Owner / Admin ของ workspace ไม่มีทางลบบัญชี (ทำได้แค่ Remove member) | H12: §20.6 | I12: ยังไม่ทดสอบ
A13: BE-DEV-01 | B13: BE-DEV | C13: device token (zyra-api · task 2.1) | D13: P0 | E13: ลงทะเบียน token | F13: POST /api/user/devices {platform, fcm_token, app_version} | G13: บันทึกลง tb_user_device · ตอบ envelope 200 | H13: task 2.1 | I13: ยังไม่ทดสอบ
... A27: BE-PUSH-09 | B27: BE-PUSH | C27: ส่ง push (zyra-notifications, zyra-ws · task 2.2–2.6) | D27: P1 | E27: secret | F27: ตรวจ config | G27: FCM_SERVICE_ACCOUNT_JSON มาจาก secret (ESO) · ไม่ hardcode · ไม่ log token / PII | H27: rule 05 | I27: ยังไม่ทดสอบ
A28: BE-PUSH-10 | B28: BE-PUSH | C28: ส่ง push (zyra-notifications, zyra-ws · task 2.2–2.6) | D28: - | E28: DND ปิด push ไหม | F28: ตั้ง Do not disturb แล้วให้คนส่ง DM | G28: ยังไม่มีมติ | H28: — | I28: Blocked | J28: รอมติ
A29: BE-WS-01 | B29: BE-WS | C29: WebSocket โหมด Lite / meeting / reconnect (zyra-ws · task 0.16, 0.19, 0.48) | D29: P0 | E29: join แบบ ghost | F29: join ด้วย client_mode: "lite" | G29: presence online · ไม่มีตำแหน่ง / ที่นั่ง · ไม่ broadcast ตำแหน่ง | H29: TD §16.2 | I29: ยังไม่ทดสอบ
A30: BE-WS-02 | B30: BE-WS | C30: WebSocket โหมด Lite / meeting / reconnect (zyra-ws · task 0.16, 0.19, 0.48) | D30: P0 | E30: ghost ส่ง move / input | F30: ส่ง move จาก lite client | G30: server ปฏิเสธ | H30: TD §16.2 | I30: ยังไม่ทดสอบ
A31: BE-WS-03 | B31: BE-WS | C31: WebSocket โหมด Lite / meeting / reconnect (zyra-ws · task 0.16, 0.19, 0.48) | D31: P0 | E31: เข้า meeting ด้วย id | F31: lite client ขอเข้า zone/meeting ด้วย id | G31: ได้เข้า media room · คนอื่นเห็นเป็น tile | H31: TD §16.2 | I31: ยังไม่ทดสอบ
A32: BE-WS-04 | B32: BE-WS | C32: WebSocket โหมด Lite / meeting / reconnect (zyra-ws · task 0.16, 0.19, 0.48) | D32: P1 | E32: ghost บนแมพของคนอื่น | F32: lite เข้า meeting | G32: broadcast ghost_join_zone · client แมพแสดง avatar เดินจาก spawn ไปห้อง · ออก meeting แล้ว avatar หาย | H32: TD §16.2 | I32: ยังไม่ทดสอบ
A33: BE-WS-05 | B33: BE-WS | C33: WebSocket โหมด Lite / meeting / reconnect (zyra-ws · task 0.16, 0.19, 0.48) | D33: P0 | E33: ขอเข้าห้องล็อก (knock เดิม) | F33: lite client ส่ง knock พร้อม zone_id | G33: ไม่เช็คตำแหน่ง · ทุกคนได้ knock_request · คนในห้องคนแรกที่ส่ง knock_decision มีผล → ผู้ขอได้ knock_granted / knock_denied · ทุกเครื่องได้ knock_decided · กดพร้อมกันไม่เกิดผลซ้ำ · ขอซ้ำติด cooldown | H33: room.go:2504 · §8.8.4 | I33: ยังไม่ทดสอบ
A34: BE-WS-06 | B34: BE-WS | C34: WebSocket โหมด Lite / meeting / reconnect (zyra-ws · task 0.16, 0.19, 0.48) | D34: P0 | E34: grace period ≥ 31 วิ | F34: ตัด connection แล้วต่อใหม่ภายใน 31 วิ | G34: presence / ห้อง meeting / ที่นั่งยังอยู่ · เกิน grace แล้วถูกนำออก | H34: TD §11.x | I34: ยังไม่ทดสอบ
A35: BE-WS-07 | B35: BE-WS | C35: WebSocket โหมด Lite / meeting / reconnect (zyra-ws · task 0.16, 0.19, 0.48) | D35: P0 | E35: backoff ฝั่ง client | F35: ดูจังหวะ reconnect | G35: 1, 2, 4, 8, 16 วิ รวม 5 ครั้ง | H35: workspace-ws.ts:82-83 | I35: ยังไม่ทดสอบ
A36: BE-WS-08 | B36: BE-WS | C36: WebSocket โหมด Lite / meeting / reconnect (zyra-ws · task 0.16, 0.19, 0.48) | D36: P1 | E36: สถานะ dnd | F36: ตั้ง dnd | G36: server รับค่า dnd · ถือว่าออกจาก meeting / circle เหมือน busy / away | H36: lib/presence-status.ts | I36: ยังไม่ทดสอบ
A37: BE-WS-09 | B37: BE-WS | C37: WebSocket โหมด Lite / meeting / reconnect (zyra-ws · task 0.16, 0.19, 0.48) | D37: P1 | E37: Spotlight จาก Lite | F37: lite client ส่ง ws:spotlight:start | G37: เริ่มได้โดยไม่ตรวจตำแหน่ง · ใช้ floor แรก + marker แรก · speaker set มีผู้เริ่ม | H37: task 0.48 | I37: ยังไม่ทดสอบ
A38: BE-WS-10 | B38: BE-WS | C38: WebSocket โหมด Lite / meeting / reconnect (zyra-ws · task 0.16, 0.19, 0.48) | D38: P1 | E38: Spotlight จาก Spatial / desktop | F38: ส่ง start ตอนไม่ได้ยืนบน marker | G38: ยังถูกปฏิเสธเหมือนเดิม | H38: task 0.48 | I38: ยังไม่ทดสอบ
A39: BE-WS-11 | B39: BE-WS | C39: WebSocket โหมด Lite / meeting / reconnect (zyra-ws · task 0.16, 0.19, 0.48) | D39: P1 | E39: Spotlight ห้ามตามสถานะ | F39: ผู้เริ่มเป็น busy / away / dnd | G39: ปฏิเสธการเริ่ม | H39: §18.7 ข้อ 13 | I39: ยังไม่ทดสอบ
A40: BE-WS-12 | B40: BE-WS | C40: WebSocket โหมด Lite / meeting / reconnect (zyra-ws · task 0.16, 0.19, 0.48) | D40: P1 | E40: Spotlight กับ meeting | F40: สมาชิก meeting คนหนึ่งส่ง ws:spotlight:meetingJoin แล้วอีกคนส่ง meetingLeave | G40: accepted_meeting_ids มีห้องนั้นหลัง join (ทั้งห้องเห็น spotlight) · หลัง leave ห้องหายจากรายการ · ส่งซ้ำไม่ error | H40: §18.9 ข้อ 3 | I40: ยังไม่ทดสอบ
... A52: BE-API-04 | B52: BE-API | C52: ทั่วไป | D52: P1 | E52: notification settings | F52: บันทึกสวิตช์ push จากมือถือ | G52: เก็บฝั่ง server · ใช้ร่วมกับ desktop · ค่า in-app เดิมไม่ถูกเปลี่ยน | H52: task 2.5 · §19.3 | I52: ยังไม่ทดสอบ
A53: BE-API-05 | B53: BE-API | C53: ทั่วไป | D53: P0 | E53: ลบบัญชี (Apple 5.1.1(v)) | F53: — | G53: รอมติ PM (ลบจริงหรือ anonymize, workspace ที่เป็น owner) | H53: open-items §4 | I53: Blocked | J53: รอมติ
A54: BE-API-06 | B54: BE-API | C54: ทั่วไป | D54: P1 | E54: GET /api/app/config | F54: เรียกโดยไม่ login · เปลี่ยนค่า env แล้ว restart pod | G54: คืน min / latest version + store url ของ iOS และ Android · เปลี่ยนค่าได้โดยไม่ต้อง build image ใหม่ | H54: §21.2 · task 0.57 | I54: ยังไม่ทดสอบ
